
try
{
	
}
catch(Exception ex)
{
	
}
finally
{
	
}