
try {
   
}
catch (const Exception& e) {
  
}